

在 JavaScript 中，中断 `Promise` 链的常见方法是通过抛出错误或返回一个被拒绝的 `Promise`。这样可以停止后续的 `then` 回调的执行，直接进入 `catch` 回调。以下是详细的解释和示例：

<a name="nnzj0"></a>
## 方法一：抛出错误

你可以在 `then` 回调中抛出一个错误来中断 `Promise` 链，错误会被最近的 `catch` 回调捕获。

```javascript
let promise = new Promise((resolve, reject) => {
  resolve('成功');
});

promise
  .then((value) => {
    console.log('第一个 then:', value);
    throw new Error('中断链');
  })
  .then((value) => {
    console.log('不会执行这个 then');
  })
  .catch((error) => {
    console.error('捕获的错误:', error.message);
  });
```

```
第一个 then: 成功
捕获的错误: 中断链
```

<a name="hItW0"></a>
## 方法二：返回一个被拒绝的 Promise

你可以在 `then` 回调中返回一个被拒绝的 `Promise` 来中断链，同样会进入 `catch` 回调。

```javascript
let promise = new Promise((resolve, reject) => {
  resolve('成功');
});

promise
  .then((value) => {
    console.log('第一个 then:', value);
    return Promise.reject('中断链');
  })
  .then((value) => {
    console.log('不会执行这个 then');
  })
  .catch((error) => {
    console.error('捕获的错误:', error);
  });
```

```
第一个 then: 成功
捕获的错误: 中断链
```

<a name="wnKg9"></a>
## 方法三：条件判断中断链

有时你可能需要根据某些条件中断 `Promise` 链。在这种情况下，可以使用条件判断来决定是否抛出错误或返回被拒绝的 `Promise`。

```javascript
let promise = new Promise((resolve, reject) => {
  resolve('成功');
});

promise
  .then((value) => {
    console.log('第一个 then:', value);
    if (value === '成功') {
      throw new Error('根据条件中断链');
    }
    return value;
  })
  .then((value) => {
    console.log('不会执行这个 then');
  })
  .catch((error) => {
    console.error('捕获的错误:', error.message);
  });
```

```
第一个 then: 成功
捕获的错误: 根据条件中断链
```

<a name="gzu6b"></a>
## 方法四：使用标志中断链

有时可能需要一种更加显式的方法来中断链，可以使用一个标志来实现。

```javascript
let shouldBreak = false;

let promise = new Promise((resolve, reject) => {
  resolve('成功');
});

promise
  .then((value) => {
    console.log('第一个 then:', value);
    shouldBreak = true; // 设置标志
    return value;
  })
  .then((value) => {
    if (shouldBreak) {
      throw new Error('中断链');
    }
    console.log('不会执行这个 then');
    return value;
  })
  .catch((error) => {
    console.error('捕获的错误:', error.message);
  });
```

```
第一个 then: 成功
捕获的错误: 中断链
```

<a name="o2rIW"></a>
## 返回 `pending` 状态的 Promise

返回一个 `pending` 状态的 `Promise` 也是一种中断 `Promise` 链的方法。这种方法的效果是使链中的后续 `then` 和 `catch` 回调都不会被调用，因为 `Promise` 永远不会被解决（`resolved`）或拒绝（`rejected`）。不过，这种方法要慎用，因为它会导致后续的回调永远不被执行，可能会使程序进入“僵死”状态。
```javascript
let promise = new Promise((resolve, reject) => {
  resolve('操作成功');
});

promise
  .then((value) => {
    console.log('第一个 then:', value);
    // 返回一个 pending 状态的 Promise 中断链
    return new Promise(() => {});
  })
  .then((value) => {
    // 这个 then 永远不会被调用
    console.log('第二个 then:', value);
  })
  .catch((error) => {
    // 这个 catch 也永远不会被调用
    console.log('捕获的错误:', error);
  });

console.log('Promise 链设置完毕');
```

```
第一个 then: 操作成功
Promise 链设置完毕
```

在这个示例中，第二个 `then` 和 `catch` 回调永远不会被执行，因为返回的 `Promise` 永远处于 `pending` 状态。

<a name="ZPp0H"></a>
### 实际应用中的考虑

使用 `pending` 状态的 `Promise` 中断链是一个有效的方法，但它通常不是最佳选择。因为它会导致后续代码永远不执行，可能会带来一些意料之外的问题。以下是一些常见场景及其更好的替代方案：

1.  **明确中断链**: 如果你确实需要中断链，考虑抛出错误或返回一个被拒绝的 `Promise`，以便可以在后续的 `catch` 中处理。 
```javascript
promise
  .then((value) => {
    console.log('第一个 then:', value);
    // 通过抛出错误中断链
    throw new Error('中断链');
  })
  .then((value) => {
    // 这个 then 不会被执行
    console.log('第二个 then:', value);
  })
  .catch((error) => {
    console.log('捕获的错误:', error.message);
  });
```
 

2.  **条件判断中断链**: 使用条件判断来决定是否中断链。 
```javascript
let shouldBreak = true;

promise
  .then((value) => {
    console.log('第一个 then:', value);
    if (shouldBreak) {
      throw new Error('中断链');
    }
    return value;
  })
  .then((value) => {
    // 根据条件判断中断链
    console.log('第二个 then:', value);
  })
  .catch((error) => {
    console.log('捕获的错误:', error.message);
  });
```
 

<a name="MHoUl"></a>
## 总结

- **返回 **`**pending**`** 状态的 **`**Promise** `可以中断链，但通常不推荐，因为它会导致后续回调永远不被执行。
- **抛出错误** 或 **返回被拒绝的 **`**Promise** `是更常见的中断链的方法，它们允许你在 `catch` 回调中处理错误。
- 使用 **条件判断** 可以更加灵活地控制链的中断逻辑。
- 中断后的错误会被最近的 `catch` 回调捕获，从而停止后续 `then` 回调的执行。选择合适的方法取决于你的具体需求和代码逻辑。

这些方法使得你的异步代码更加可预测和可调试，避免陷入难以检测和修复的状态。
